Workbook
Name UPDATE: '[1]Data Sheet'!$E$1
Name UPDATE: '[2]Data Sheet'!$E$1

Sheet Intro
F6: Financial Modeling & Valuation Report
J13: Prepared By
J14: Shivalika Singh

Sheet Table of Contents
B5: Table of Contents
B10: 1. One Page Profile
B11: 2. Historical Financial Statement
B12: 3. Forecasting
B13: 4. Ratio Analysis
B14: 5. Common Size Statement
B15: 6. Reggretion Beta
B16: 7. WACC
B17: 8. Relative Valuation
B18: 9. DCF
B19: 10. VAR
B20: 11. Dupont Analysis
B21: 12. Altman's Z Score

Sheet one page profile
B2: ='[1]Data Sheet'!B1&" - One Page Profile" -> BAJAJ AUTO LTD - One Page Profile
C4: Bajaj Auto, the flagship company of Bajaj Group, is a two-wheeler and three-wheeler manufacturing company that exports to 79 countries across several countries in Latin America, Southeast Asia, and many more. Its headquarter is in Pune, India. It has acquired 48% of the KTM Brand which manufactures sports and super sports two-wheelers, which was 14% in 2007 when the company first acquired KTM.
B6: (INR)crs.
B9: Key Financial Metrics | C9: ='[1]Data Sheet'!C16 -> 42825 | D9: ='[1]Data Sheet'!D16 -> 43190 | E9: ='[1]Data Sheet'!E16 -> 43555 | F9: ='[1]Data Sheet'!F16 -> 43921 | G9: ='[1]Data Sheet'!G16 -> 44286 | H9: ='[1]Data Sheet'!H16 -> 44651 | I9: ='[1]Data Sheet'!I16 -> 45016 | J9: ='[1]Data Sheet'!J16 -> 45382 | K9: ='[1]Data Sheet'!K16 -> 45747 | M9: Capital Structure
B11: Total Sales | C11: ='[1]Data Sheet'!C17 -> 21754.72 | D11: ='[1]Data Sheet'!D17 -> 25209.93 | E11: ='[1]Data Sheet'!E17 -> 30357.63 | F11: ='[1]Data Sheet'!F17 -> 29918.65 | G11: ='[1]Data Sheet'!G17 -> 27741.08 | H11: ='[1]Data Sheet'!H17 -> 33144.71 | I11: ='[1]Data Sheet'!I17 -> 36455.38 | J11: ='[1]Data Sheet'!J17 -> 44870.43 | K11: ='[1]Data Sheet'!K17 -> 50994.55 | M11: Share Price as on XXX | Q11: ='[1]Data Sheet'!B8 -> 9164
B12: Sales Growth (y-o-y) | C12: ='[1]Data Sheet'!C34 -> -0.036279846 | D12: ='[1]Data Sheet'!D34 -> 0.15882576 | E12: ='[1]Data Sheet'!E34 -> 0.20419335 | F12: ='[1]Data Sheet'!F34 -> -0.014460286 | G12: ='[1]Data Sheet'!G34 -> -0.07278303 | H12: ='[1]Data Sheet'!H34 -> 0.19478802 | I12: ='[1]Data Sheet'!I34 -> 0.099885321 | J12: ='[1]Data Sheet'!J34 -> 0.2308315 | K12: ='[1]Data Sheet'!K34 -> 0.13648454 | M12: Numer of Shares O/S | Q12: ='[1]Data Sheet'!B6 -> 27.931626
B13: Gross Profit Margins (%) | C13: ='[1]Data Sheet'!C36 -> 0.2481935 | D13: ='[1]Data Sheet'!D36 -> 0.24181701 | E13: ='[1]Data Sheet'!E36 -> 0.21206497 | F13: ='[1]Data Sheet'!F36 -> 0.21972749 | G13: ='[1]Data Sheet'!G36 -> 0.20575803 | H13: ='[1]Data Sheet'!H36 -> 0.20759029 | I13: ='[1]Data Sheet'!I36 -> 0.21339018 | J13: ='[1]Data Sheet'!J36 -> 0.229797 | K13: ='[1]Data Sheet'!K36 -> 0.25236716
B14: EBITDA Margins (%) | C14: ='[1]Data Sheet'!C38 -> 0.19955531 | D14: ='[1]Data Sheet'!D38 -> 0.19298586 | E14: ='[1]Data Sheet'!E38 -> 0.16750583 | F14: ='[1]Data Sheet'!F38 -> 0.16656233 | G14: ='[1]Data Sheet'!G38 -> 0.16217177 | H14: ='[1]Data Sheet'!H38 -> 0.1700036 | I14: ='[1]Data Sheet'!I38 -> 0.17182594 | J14: ='[1]Data Sheet'!J38 -> 0.19193041 | K14: ='[1]Data Sheet'!K38 -> 0.18847936 | M14: Market Capitalization | Q14: =Q11*Q12 -> 255965.42
B15: EBIT Margins (%) | C15: ='[1]Data Sheet'!C40 -> 0.1854301 | D15: ='[1]Data Sheet'!D40 -> 0.18049872 | E15: ='[1]Data Sheet'!E40 -> 0.15875383 | F15: ='[1]Data Sheet'!F40 -> 0.15832566 | G15: ='[1]Data Sheet'!G40 -> 0.1528221 | H15: ='[1]Data Sheet'!H40 -> 0.16186474 | I15: ='[1]Data Sheet'!I40 -> 0.16398485 | J15: ='[1]Data Sheet'!J40 -> 0.183801 | K15: ='[1]Data Sheet'!K40 -> 0.18035633 | M15: Less: Cash & Equivalents | Q15: ='[1]Data Sheet'!K81*-1 -> -2847.6
B16: Net Profit Margins (%) | C16: ='[1]Data Sheet'!C44 -> 0.11604424 | D16: ='[1]Data Sheet'!D44 -> 0.11243903 | E16: ='[1]Data Sheet'!E44 -> 0.09180328 | F16: ='[1]Data Sheet'!F44 -> 0.10874521 | G16: ='[1]Data Sheet'!G44 -> 0.10267733 | H16: ='[1]Data Sheet'!H44 -> 0.1167755 | I16: ='[1]Data Sheet'!I44 -> 0.11402569 | J16: ='[1]Data Sheet'!J44 -> 0.13048839 | K16: ='[1]Data Sheet'!K44 -> 0.11588474 | M16: Add: Total Debt | Q16: ='[1]Data Sheet'!K71 -> 9364.16
B17: Earnings Per Share (in Rs) | C17: ='[1]Data Sheet'!C45 -> 87.23255 | D17: ='[1]Data Sheet'!D45 -> 97.946786 | E17: ='[1]Data Sheet'!E45 -> 96.300276 | F17: ='[1]Data Sheet'!F45 -> 112.4226 | G17: ='[1]Data Sheet'!G45 -> 98.423635 | H17: ='[1]Data Sheet'!H45 -> 133.74188 | I17: ='[1]Data Sheet'!I45 -> 146.88516 | J17: ='[1]Data Sheet'!J45 -> 209.70881 | K17: ='[1]Data Sheet'!K45 -> 211.58217
B18: EPS Growth (y-o-y) | C18: ='[1]Data Sheet'!C46 -> -0.15680747 | D18: ='[1]Data Sheet'!D46 -> 0.12282384 | E18: ='[1]Data Sheet'!E46 -> -0.016810251 | F18: ='[1]Data Sheet'!F46 -> 0.16741719 | G18: ='[1]Data Sheet'!G46 -> -0.1245209 | H18: ='[1]Data Sheet'!H46 -> 0.35883906 | I18: ='[1]Data Sheet'!I46 -> 0.098273475 | J18: ='[1]Data Sheet'!J46 -> 0.42770592 | K18: ='[1]Data Sheet'!K46 -> 0.0089331431
B19: Dividend Per Share (in Rs) | C19: ='[1]Data Sheet'!C47 -> 54.994471 | D19: ='[1]Data Sheet'!D47 -> 59.99378 | E19: ='[1]Data Sheet'!E47 -> 59.99378 | F19: ='[1]Data Sheet'!F47 -> 119.98756 | G19: ='[1]Data Sheet'!G47 -> 139.98549 | H19: ='[1]Data Sheet'!H47 -> 139.98549 | I19: ='[1]Data Sheet'!I47 -> 139.98021 | J19: ='[1]Data Sheet'!J47 -> 79.994269 | K19: ='[1]Data Sheet'!K47 -> 209.96992 | M19: Enterprise Value | Q19: =SUM(Q14:Q16) -> 262481.98
B20: DPS Growth (y-o-y) | C20: ='[1]Data Sheet'!C48 -> 0 | D20: ='[1]Data Sheet'!D48 -> 0.090905664 | E20: ='[1]Data Sheet'!E48 -> 0 | F20: ='[1]Data Sheet'!F48 -> 1 | G20: ='[1]Data Sheet'!G48 -> 0.16666667 | H20: ='[1]Data Sheet'!H48 -> 0 | I20: ='[1]Data Sheet'!I48 -> -3.7683912e-05 | J20: ='[1]Data Sheet'!J48 -> -0.42853159 | K20: ='[1]Data Sheet'!K48 -> 1.6248121
B22: Key Financial Ratios | C22: =C9 -> 42825 | D22: =D9 -> 43190 | E22: =E9 -> 43555 | F22: =F9 -> 43921 | G22: =G9 -> 44286 | H22: =H9 -> 44651 | I22: =I9 -> 45016 | J22: =J9 -> 45382 | K22: =K9 -> 45747 | M22: Recent Updates
B24: Price to Earnings | C24: ='[1]Data Sheet'!C95 -> 32.160587 | D24: ='[1]Data Sheet'!D95 -> 28.022359 | E24: ='[1]Data Sheet'!E95 -> 30.229404 | F24: ='[1]Data Sheet'!F95 -> 17.988821 | G24: ='[1]Data Sheet'!G95 -> 37.293888 | H24: ='[1]Data Sheet'!H95 -> 27.313808 | I24: ='[1]Data Sheet'!I95 -> 26.447532 | J24: ='[1]Data Sheet'!J95 -> 43.623107 | K24: ='[1]Data Sheet'!K95 -> 37.237779 | M24: • Bajaj Auto reported a 23.7% rise in Q2 (quarter ended Sept 30, 2025) profit, driven largely by strong exports of motorcycles even though domestic demand remained sluggish.
B25: EV/EBITDA | C25: ='[1]Data Sheet'!C90 -> 19.503374 | D25: ='[1]Data Sheet'!D90 -> 17.132986 | E25: ='[1]Data Sheet'!E90 -> 17.485421 | F25: ='[1]Data Sheet'!F90 -> 12.653895 | G25: ='[1]Data Sheet'!G90 -> 24.899108 | H25: ='[1]Data Sheet'!H90 -> 19.523831 | I25: ='[1]Data Sheet'!I90 -> 18.362583 | J25: ='[1]Data Sheet'!J90 -> 30.752706 | K25: ='[1]Data Sheet'!K90 -> 24.567635
B26: EV/Sales | C26: ='[1]Data Sheet'!C91 -> 3.892002 | D26: ='[1]Data Sheet'!D91 -> 3.306424 | E26: ='[1]Data Sheet'!E91 -> 2.9289099 | F26: ='[1]Data Sheet'!F91 -> 2.1076622 | G26: ='[1]Data Sheet'!G91 -> 4.0379323 | H26: ='[1]Data Sheet'!H91 -> 3.3191215 | I26: ='[1]Data Sheet'!I91 -> 3.1551682 | J26: ='[1]Data Sheet'!J91 -> 5.9023795 | K26: ='[1]Data Sheet'!K91 -> 4.6304921
B27: Price to Book Value | C27: ='[1]Data Sheet'!C93 -> 4.5467703 | D27: ='[1]Data Sheet'!D93 -> 3.8888952 | E27: ='[1]Data Sheet'!E93 -> 3.6260619 | F27: ='[1]Data Sheet'!F93 -> 2.7018093 | G27: ='[1]Data Sheet'!G93 -> 3.8948957 | H27: ='[1]Data Sheet'!H93 -> 3.5404909 | I27: ='[1]Data Sheet'!I93 -> 3.7443004 | J27: ='[1]Data Sheet'!J93 -> 8.8188914 | K27: ='[1]Data Sheet'!K93 -> 6.2535993
B28: Return on Equity(%) | C28: ='[1]Data Sheet'!C94 -> 0.1413771 | D28: ='[1]Data Sheet'!D94 -> 0.1387783 | E28: ='[1]Data Sheet'!E94 -> 0.11995148 | F28: ='[1]Data Sheet'!F94 -> 0.15019379 | G28: ='[1]Data Sheet'!G94 -> 0.10443791 | H28: ='[1]Data Sheet'!H94 -> 0.12962275 | I28: ='[1]Data Sheet'!I94 -> 0.14157466 | J28: ='[1]Data Sheet'!J94 -> 0.20216101 | K28: ='[1]Data Sheet'!K94 -> 0.16793696 | M28: • The company has completed acquisition of a majority stake in Austrian motorcycle maker KTM — through restructuring of its European holding — giving Bajaj full controlling interest in global KTM business.
B29: Return on Capital Employed (%) | C29: ='[3]Ratio Analysis'!$C$29 -> 0.22440335 | D29: ='[3]Ratio Analysis'!$C$29 -> 0.22440335 | E29: ='[3]Ratio Analysis'!$C$29 -> 0.22440335 | F29: ='[3]Ratio Analysis'!$C$29 -> 0.22440335 | G29: ='[3]Ratio Analysis'!$C$29 -> 0.22440335 | H29: ='[3]Ratio Analysis'!$C$29 -> 0.22440335 | I29: ='[3]Ratio Analysis'!$C$29 -> 0.22440335 | J29: ='[3]Ratio Analysis'!$C$29 -> 0.22440335 | K29: ='[3]Ratio Analysis'!$C$29 -> 0.22440335
B31: Top 10 Shareholders | F31: ='[1]Input Sheet'!C3 -> N. Shares (in Crs.) | H31: Shareholding (%) | J31: Market Value (in Crs.)
B33: ='[1]Input Sheet'!B15 -> Bajaj Holdings And Investment Limited | G33: ='[1]Input Sheet'!C4 -> 9.5547251 | I33: ='[1]Input Sheet'!D4 -> 0.3421 | K33: ='[1]Input Sheet'!E4 -> 86412.934 | M33: • Bajaj Auto has entered the electric-rickshaw (e-rickshaw) segment with launch of its new model Bajaj Riki featuring ~149 km range on single charge.
B34: ='[1]Input Sheet'!B16 -> Jamnalal Sons Pvt Limited | G34: ='[1]Input Sheet'!C5 -> 2.5960841 | I34: ='[1]Input Sheet'!D5 -> 0.093 | K34: ='[1]Input Sheet'!E5 -> 23478.985
B35: ='[1]Input Sheet'!B17 -> Lici Ulip-Growth Fund | G35: ='[1]Input Sheet'!C6 -> 1.0022378 | I35: ='[1]Input Sheet'!D6 -> 0.0359 | K35: ='[1]Input Sheet'!E6 -> 9064.2387
B36: ='[1]Input Sheet'!B18 -> Jaya Hind Industries Private Limited | G36: ='[1]Input Sheet'!C7 -> 0.993166 | I36: ='[1]Input Sheet'!D7 -> 0.0356 | K36: ='[1]Input Sheet'!E7 -> 8982.1933
B37: ='[1]Input Sheet'!B19 -> Maharashtra Scooters Limited | G37: ='[1]Input Sheet'!C8 -> 0.6879333 | I37: ='[1]Input Sheet'!D8 -> 0.0246 | K37: ='[1]Input Sheet'!E8 -> 6221.6688 | M37: • The company plans to expand “Riki” e-rickshaw rollout to 200 cities by Q1 2026, up from the current pilot in a handful of cities — signalling a push into last-mile urban mobility nationwide.
B38: ='[1]Input Sheet'!B20 -> Hdfc Mutual Fund - Hdfc Business Cycle Fund | G38: ='[1]Input Sheet'!C9 -> 0.6214942 | I38: ='[1]Input Sheet'!D9 -> 0.0223 | K38: ='[1]Input Sheet'!E9 -> 5620.7935
B39: ='[1]Input Sheet'!B21 -> Bajaj Sevashram Pvt Limited | G39: ='[1]Input Sheet'!C10 -> 0.4408288 | I39: ='[1]Input Sheet'!D10 -> 0.0158 | K39: ='[1]Input Sheet'!E10 -> 3986.8557
B40: ='[1]Input Sheet'!B22 -> Bachhraj And Company Pvt Limited | G40: ='[1]Input Sheet'!C11 -> 0.3646362 | I40: ='[1]Input Sheet'!D11 -> 0.0131 | K40: ='[1]Input Sheet'!E11 -> 3297.7698
B41: ='[1]Input Sheet'!B23 -> Yamuna Trust | G41: ='[1]Input Sheet'!C12 -> 0.3615269 | I41: ='[1]Input Sheet'!D12 -> 0.0129 | K41: ='[1]Input Sheet'!E12 -> 3269.6493 | M41: • On 27 Nov 2025, some brokerage analysts (e.g. from Anand Rathi) flagged Bajaj Auto shares as a “top buy” — citing bullish technical signals (like RSI divergences, engulfing patterns) for short-term gains.
B42: ='[1]Input Sheet'!B24 -> Sbi Consumption Opportunities Fund | G42: ='[1]Input Sheet'!C13 -> 0.2988761 | I42: ='[1]Input Sheet'!D13 -> 0.0107 | K42: ='[1]Input Sheet'!E13 -> 2703.0354
B44: Managerial Remuneration | F44: Designation | H44: Remunration | J44: X of Median sallary
B46: Mr. Rajiv Bajaj | F46: MD & CEO | H46: =585824725/10000000 -> 58.582473 | J46: 575.47 | M46: • In the same session, the broader auto index saw profit-booking after reaching record highs — and Bajaj Auto was among the leading losers of the day (alongside peers), showing current volatility in the stock.
B47: Mr. Pradeep Shrivastva | F47: ED | H47: =283317842/10000000 -> 28.331784 | J47: 278.31
B48: Mr. Rakesh Sharma | F48: ED | H48: =168130754/10000000 -> 16.813075 | J48: 165.16
B50: Notes:
B51: Pradeep Shrivastava and Rakesh Sharma, the executive directors of the Company are entitled to employee stock options as per Bajaj Auto Employee Stock Option Scheme 2019, as amended. The above remuneration is exclusive of fair value of options granted as per Black Scholes model in the year of vesting. | M51: Sources:
M52: Screener.in, Yahoo Finance, Bajaj Auto LTD Annual Report 2025, NSE India, Wikipedia.
B55: ='[1]Data Sheet'!B54&" - One Page Profile" -> 10311.91 - One Page Profile | C55: ='[1]Data Sheet'!C54&" - One Page Profile" -> 10838.24 - One Page Profile | D55: ='[1]Data Sheet'!D54&" - One Page Profile" -> 12165.33 - One Page Profile | E55: ='[1]Data Sheet'!E54&" - One Page Profile" -> 11554.95 - One Page Profile | F55: ='[1]Data Sheet'!F54&" - One Page Profile" -> 11932.07 - One Page Profile | G55: ='[1]Data Sheet'!G54&" - One Page Profile" -> 13247.28 - One Page Profile | H55: ='[1]Data Sheet'!H54&" - One Page Profile" -> 13168.88 - One Page Profile | I55: ='[1]Data Sheet'!I54&" - One Page Profile" -> 12646.32 - One Page Profile | ... Q55: ='[1]Data Sheet'!Q54&" - One Page Profile" -> - One Page Profile

Sheet Historical FS
B2: Return on Equity(ROE) | C2: Return on Equity(ROE) | D2: Return on Equity(ROE) | E2: Return on Equity(ROE) | F2: Return on Equity(ROE) | G2: Return on Equity(ROE) | H2: Return on Equity(ROE) | I2: Return on Equity(ROE) | L2: Return on Equity(ROE)
B4: ='[2]Data Sheet'!B1 -> BAJAJ AUTO LTD
B5: =CONCATENATE(" ",VLOOKUP(B4,'[2]LIST OF STOCKS'!B5:D5444,3,FALSE)," | ","Bse Code: ",VLOOKUP(B4,'[2]LIST OF STOCKS'!B5:E5444,2,FALSE),) -> BAJAJ-AUTO | Bse Code: 532977
B6: INR (Crs.)
B8: ="Historical Financial Statement - "&'[2]Balance Sheet'!A1 -> Historical Financial Statement - BAJAJ AUTO LTD
B9: Years | C9: =IFERROR('[2]Data Sheet'!C16,0) -> 42825 | D9: =IFERROR('[2]Data Sheet'!D16,0) -> 43190 | E9: =IFERROR('[2]Data Sheet'!E16,0) -> 43555 | F9: =IFERROR('[2]Data Sheet'!F16,0) -> 43921 | G9: =IFERROR('[2]Data Sheet'!G16,0) -> 44286 | H9: =IFERROR('[2]Data Sheet'!H16,0) -> 44651 | I9: =IFERROR('[2]Data Sheet'!I16,0) -> 45016 | J9: =IFERROR('[2]Data Sheet'!J16,0) -> 45382 | K9: =IFERROR('[2]Data Sheet'!K16,0) -> 45747 | L9: LTM
B11: Income Statement
B13: Sales | C13: ='[2]Data Sheet'!C17 -> 21754.72 | D13: ='[2]Data Sheet'!D17 -> 25209.93 | E13: ='[2]Data Sheet'!E17 -> 30357.63 | F13: ='[2]Data Sheet'!F17 -> 29918.65 | G13: ='[2]Data Sheet'!G17 -> 27741.08 | H13: ='[2]Data Sheet'!H17 -> 33144.71 | I13: ='[2]Data Sheet'!I17 -> 36455.38 | J13: ='[2]Data Sheet'!J17 -> 44870.43 | K13: ='[2]Data Sheet'!K17 -> 50994.55 | L13: =IFERROR(SUM('[2]Data Sheet'!H42:K42),0) -> 54683.29
A14: # | B14: Sales Growth | C14: - | D14: =IFERROR(D13/C13-1,0) -> 0.15882576 | E14: =IFERROR(E13/D13-1,0) -> 0.20419335 | F14: =IFERROR(F13/E13-1,0) -> -0.014460286 | G14: =IFERROR(G13/F13-1,0) -> -0.07278303 | H14: =IFERROR(H13/G13-1,0) -> 0.19478802 | I14: =IFERROR(I13/H13-1,0) -> 0.099885321 | J14: =IFERROR(J13/I13-1,0) -> 0.2308315 | K14: =IFERROR(K13/J13-1,0) -> 0.13648454 | L14: =IFERROR(L13/I13-1,0) -> 0.50000603
B16: COGS | C16: =SUM('[2]Data Sheet'!C18:C22) -> 16355.34 | D16: =SUM('[2]Data Sheet'!D18:D22) -> 19113.74 | E16: =SUM('[2]Data Sheet'!E18:E22) -> 23919.84 | F16: =SUM('[2]Data Sheet'!F18:F22) -> 23344.7 | G16: =SUM('[2]Data Sheet'!G18:G22) -> 22033.13 | H16: =SUM('[2]Data Sheet'!H18:H22) -> 26264.19 | I16: =SUM('[2]Data Sheet'!I18:I22) -> 28676.16 | J16: =SUM('[2]Data Sheet'!J18:J22) -> 34559.34 | K16: =SUM('[2]Data Sheet'!K18:K22) -> 38125.2 | L16: =IFERROR(SUM('[2]Data Sheet'!J18:J22)-'[2]Data Sheet'!J19,0) -> 34483
B17: COGS % Sales | C17: =C16/C13 -> 0.7518065 | D17: =D16/D13 -> 0.75818299 | E17: =E16/E13 -> 0.78793503 | F17: =F16/F13 -> 0.78027251 | G17: =G16/G13 -> 0.79424197 | H17: =H16/H13 -> 0.79240971 | I17: =I16/I13 -> 0.78660982 | L17: =L16/L13 -> 0.63059483
B19: Gross Profit | C19: =C13-C16 -> 5399.38 | D19: =D13-D16 -> 6096.19 | E19: =E13-E16 -> 6437.79 | F19: =F13-F16 -> 6573.95 | G19: =G13-G16 -> 5707.95 | H19: =H13-H16 -> 6880.52 | I19: =I13-I16 -> 7779.22 | J19: =J13-J16 -> 10311.09 | ... L19: =L13-L16 -> 20200.29
B20: Gross Margins | C20: =C19/C13 -> 0.2481935 | D20: =D19/D13 -> 0.24181701 | E20: =E19/E13 -> 0.21206497 | F20: =F19/F13 -> 0.21972749 | G20: =G19/G13 -> 0.20575803 | H20: =H19/H13 -> 0.20759029 | I20: =I19/I13 -> 0.21339018 | J20: =J19/J13 -> 0.229797 | ... L20: =L19/L13 -> 0.36940517
B22: Selling & General expenses | C22: =IFERROR(SUM('[2]Data Sheet'!C23:C24),0) -> 1058.11 | D22: =IFERROR(SUM('[2]Data Sheet'!D23:D24),0) -> 1231.03 | E22: =IFERROR(SUM('[2]Data Sheet'!E23:E24),0) -> 1352.71 | F22: =IFERROR(SUM('[2]Data Sheet'!F23:F24),0) -> 1590.63 | G22: =IFERROR(SUM('[2]Data Sheet'!G23:G24),0) -> 1209.13 | H22: =IFERROR(SUM('[2]Data Sheet'!H23:H24),0) -> 1245.8 | I22: =IFERROR(SUM('[2]Data Sheet'!I23:I24),0) -> 1515.24 | J22: =IFERROR(SUM('[2]Data Sheet'!J23:J24),0) -> 1699.09 | K22: =IFERROR(SUM('[2]Data Sheet'!K23:K24),0) -> 3257.93
B23: S&G Exp % Sales | C23: =C22/C13 -> 0.048638181 | D23: =D22/D13 -> 0.048831155 | E23: =E22/E13 -> 0.044559144 | F23: =F22/F13 -> 0.053165166 | G23: =G22/G13 -> 0.043586263 | H23: =H22/H13 -> 0.037586692 | I23: =I22/I13 -> 0.041564236 | J23: =J22/J13 -> 0.037866586 | K23: =K22/K13 -> 0.063887808
B25: EBITDA | C25: =C19-C22 -> 4341.27 | D25: =D19-D22 -> 4865.16 | E25: =E19-E22 -> 5085.08 | F25: =F19-F22 -> 4983.32 | G25: =G19-G22 -> 4498.82 | H25: =H19-H22 -> 5634.72 | I25: =I19-I22 -> 6263.98 | J25: =J19-J22 -> 8612 | K25: =K19-K22 -> 9611.42 | L25: =IFERROR(SUM('[2]Data Sheet'!H51:K51),0) -> 10730.21
B26: EBITDA Margins | C26: =C25/C13 -> 0.19955531 | D26: =D25/D13 -> 0.19298586 | E26: =E25/E13 -> 0.16750583 | F26: =F25/F13 -> 0.16656233 | G26: =G25/G13 -> 0.16217177 | H26: =H25/H13 -> 0.1700036 | I26: =I25/I13 -> 0.17182594 | J26: =J25/J13 -> 0.19193041 | ... L26: =L25/L13 -> 0.19622466
B28: Interest | C28: =IFERROR('[2]Data Sheet'!C27,0) -> 1.4 | D28: =IFERROR('[2]Data Sheet'!D27,0) -> 1.31 | E28: =IFERROR('[2]Data Sheet'!E27,0) -> 4.48 | F28: =IFERROR('[2]Data Sheet'!F27,0) -> 3.16 | G28: =IFERROR('[2]Data Sheet'!G27,0) -> 6.66 | H28: =IFERROR('[2]Data Sheet'!H27,0) -> 8.66 | I28: =IFERROR('[2]Data Sheet'!I27,0) -> 39.51 | J28: =IFERROR('[2]Data Sheet'!J27,0) -> 60.36 | K28: =IFERROR('[2]Data Sheet'!K27,0) -> 388.9 | L28: =IFERROR(SUM('[2]Data Sheet'!H46:K46),0) -> 777.33
B29: Interest % sales | C29: =C28/C13 -> 6.4353851e-05 | D29: =D28/D13 -> 5.1963651e-05 | E29: =E28/E13 -> 0.0001475741 | F29: =F28/F13 -> 0.00010561974 | G29: =G28/G13 -> 0.00024007717 | H29: =H28/H13 -> 0.0002612785 | I29: =I28/I13 -> 0.0010837907 | J29: =J28/J13 -> 0.0013452066 | ... L29: =L28/L13 -> 0.014215129
B31: Depreciation | C31: =IFERROR('[2]Data Sheet'!C26,0) -> 307.29 | D31: =IFERROR('[2]Data Sheet'!D26,0) -> 314.8 | E31: =IFERROR('[2]Data Sheet'!E26,0) -> 265.69 | F31: =IFERROR('[2]Data Sheet'!F26,0) -> 246.43 | G31: =IFERROR('[2]Data Sheet'!G26,0) -> 259.37 | H31: =IFERROR('[2]Data Sheet'!H26,0) -> 269.76 | I31: =IFERROR('[2]Data Sheet'!I26,0) -> 285.85 | J31: =IFERROR('[2]Data Sheet'!J26,0) -> 364.77 | K31: =IFERROR('[2]Data Sheet'!K26,0) -> 414.23 | L31: =IFERROR(SUM('[2]Data Sheet'!H45:K45),0) -> 457.45
B32: Depriciation % sales | C32: =C31/C13 -> 0.014125211 | D32: =D31/D13 -> 0.012487143 | E32: =E31/E13 -> 0.0087520007 | F32: =F31/F13 -> 0.0082366684 | G32: =G31/G13 -> 0.009349672 | H32: =H31/H13 -> 0.0081388553 | I32: =I31/I13 -> 0.0078410923 | J32: =J31/J13 -> 0.0081294073 | ... L32: =L31/L13 -> 0.008365444
B34: Earnings before Tax | C34: =IFERROR(C25-SUM(C28:C31),0) -> 4032.5799 | D34: =D25-SUM(D28:D31) -> 4549.0499 | E34: =E25-SUM(E28:E31) -> 4814.9099 | F34: =F25-SUM(F28:F31) -> 4733.7299 | G34: =G25-SUM(G28:G31) -> 4232.7898 | H34: =H25-SUM(H28:H31) -> 5356.2997 | I34: =I25-SUM(I28:I31) -> 5938.6189 | J34: =J25-SUM(J28:J31) -> 8186.8687 | K34: =K25-SUM(K28:K31) -> 8808.2824 | L34: =L25-SUM(L28:L31) -> 9495.4158
B35: EBT % Sales | C35: =C34/C13 -> 0.18536575 | D35: =D34/D13 -> 0.18044675 | E35: =E34/E13 -> 0.15860625 | F35: =F34/F13 -> 0.15822004 | G35: =G34/G13 -> 0.15258201 | H35: =H34/H13 -> 0.16160346 | I35: =I34/I13 -> 0.16290103 | J35: =J34/J13 -> 0.18245577 | ... L35: =L34/L13 -> 0.17364383
B37: Tax | C37: =IFERROR('[2]Data Sheet'!C29,0) -> 1508.07 | D37: =IFERROR('[2]Data Sheet'!D29,0) -> 1714.47 | E37: =IFERROR('[2]Data Sheet'!E29,0) -> 2027.98 | F37: =IFERROR('[2]Data Sheet'!F29,0) -> 1480.22 | G37: =IFERROR('[2]Data Sheet'!G29,0) -> 1384.41 | H37: =IFERROR('[2]Data Sheet'!H29,0) -> 1485.81 | I37: =IFERROR('[2]Data Sheet'!I29,0) -> 1781.77 | J37: =IFERROR('[2]Data Sheet'!J29,0) -> 2331.8 | K37: =IFERROR('[2]Data Sheet'!K29,0) -> 2898.8 | L37: =IFERROR(SUM('[2]Data Sheet'!H48:K48),0) -> 2990
B38: Effective Tax Rate | C38: =C37/C34 -> 0.37397151 | D38: =D37/D34 -> 0.37688529 | E38: =E37/E34 -> 0.42118753 | F38: =F37/F34 -> 0.31269634 | G38: =G37/G34 -> 0.32706798 | H38: =H37/H34 -> 0.27739486 | I38: =I37/I34 -> 0.30003104 | J38: =J37/J34 -> 0.28482196 | ... L38: =L37/L34 -> 0.31488879
B40: Net profit | C40: =IFERROR(C34-C37,0) -> 2524.5099 | D40: =IFERROR(D34-D37,0) -> 2834.5799 | E40: =IFERROR(E34-E37,0) -> 2786.9299 | F40: =IFERROR(F34-F37,0) -> 3253.5099 | G40: =IFERROR(G34-G37,0) -> 2848.3798 | H40: =IFERROR(H34-H37,0) -> 3870.4897 | I40: =IFERROR(I34-I37,0) -> 4156.8489 | J40: =IFERROR(J34-J37,0) -> 5855.0687 | ... L40: =IFERROR(L34-L37,0) -> 6505.4158
B41: Net margins | C41: =C40/C13 -> 0.11604424 | D41: =D40/D13 -> 0.11243902 | E41: =E40/E13 -> 0.091803275 | F41: =F40/F13 -> 0.10874521 | G41: =G40/G13 -> 0.10267732 | H41: =H40/H13 -> 0.11677549 | I41: =I40/I13 -> 0.11402566 | J41: =J40/J13 -> 0.13048836 | ... L41: =L40/L13 -> 0.11896533
B43: No. of Equity shares | C43: =IFERROR('[2]Data Sheet'!C93,0) -> 28.94 | D43: =IFERROR('[2]Data Sheet'!D93,0) -> 28.94 | E43: =IFERROR('[2]Data Sheet'!E93,0) -> 28.94 | F43: =IFERROR('[2]Data Sheet'!F93,0) -> 28.94 | G43: =IFERROR('[2]Data Sheet'!G93,0) -> 28.94 | H43: =IFERROR('[2]Data Sheet'!H93,0) -> 28.94 | I43: =IFERROR('[2]Data Sheet'!I93,0) -> 28.3 | J43: =IFERROR('[2]Data Sheet'!J93,0) -> 27.92 | K43: =IFERROR('[2]Data Sheet'!K93,0) -> 27.93 | L43: =IFERROR(SUM('[2]Data Sheet'!H93:K93),0) -> 113.09
B45: EPS | C45: =IFERROR(C40/C43,0) -> 87.232548 | D45: =IFERROR(D40/D43,0) -> 97.946785 | E45: =IFERROR(E40/E43,0) -> 96.300271 | F45: =IFERROR(F40/F43,0) -> 112.42259 | G45: =IFERROR(G40/G43,0) -> 98.423627 | H45: =IFERROR(H40/H43,0) -> 133.74187 | I45: =IFERROR(I40/I43,0) -> 146.88512 | J45: =IFERROR(J40/J43,0) -> 209.70876 | ... L45: =IFERROR(L40/L43,0) -> 57.524235
B46: EPS Growth % | D46: =D45/C45-1 -> 0.12282384 | E46: =E45/D45-1 -> -0.016810285 | F46: =F45/E45-1 -> 0.16741722 | G46: =G45/F45-1 -> -0.12452095 | H46: =H45/G45-1 -> 0.35883908 | I46: =I45/H45-1 -> 0.098273263 | J46: =J45/I45-1 -> 0.42770596 | K46: =K45/J45-1 -> 0.0089320729 | L46: =L45/I45 -> 0.39162738
B48: Dividend per share | C48: =IFERROR('[2]Data Sheet'!C31/'Historical FS'!C43,0) -> 54.994471 | D48: =IFERROR('[2]Data Sheet'!D31/'Historical FS'!D43,0) -> 59.99378 | E48: =IFERROR('[2]Data Sheet'!E31/'Historical FS'!E43,0) -> 59.99378 | F48: =IFERROR('[2]Data Sheet'!F31/'Historical FS'!F43,0) -> 119.98756 | G48: =IFERROR('[2]Data Sheet'!G31/'Historical FS'!G43,0) -> 139.98549 | H48: =IFERROR('[2]Data Sheet'!H31/'Historical FS'!H43,0) -> 139.98549 | I48: =IFERROR('[2]Data Sheet'!I31/'Historical FS'!I43,0) -> 139.98021 | J48: =IFERROR('[2]Data Sheet'!J31/'Historical FS'!J43,0) -> 79.994269 | K48: =IFERROR('[2]Data Sheet'!K31/'Historical FS'!K43,0) -> 209.96992 | L48: =IFERROR('[2]Data Sheet'!J31/'Historical FS'!L43,0) -> 19.749226
B49: Dividend Payout ratio | C49: =IFERROR(C48/C45,0) -> 0.63043523 | D49: =IFERROR(D48/D45,0) -> 0.61251403 | E49: =IFERROR(E48/E45,0) -> 0.62298662 | F49: =IFERROR(F48/F45,0) -> 1.0672904 | G49: =IFERROR(G48/G45,0) -> 1.4222752 | H49: =IFERROR(H48/H45,0) -> 1.0466841 | I49: =IFERROR(I48/I45,0) -> 0.95299109 | J49: =IFERROR(J48/J45,0) -> 0.38145411 | ... L49: =IFERROR(L48/L45,0) -> 0.3433201
B51: Retained Earnings | C51: =IFERROR(1-C49,0) -> 0.36956477 | D51: =IFERROR(1-D49,0) -> 0.38748597 | E51: =IFERROR(1-E49,0) -> 0.37701338 | F51: =IFERROR(1-F49,0) -> -0.067290438 | G51: =IFERROR(1-G49,0) -> -0.42227524 | H51: =IFERROR(1-H49,0) -> -0.046684082 | I51: =IFERROR(1-I49,0) -> 0.047008905 | J51: =IFERROR(1-J49,0) -> 0.61854589 | ... L51: =IFERROR(1-L49,0) -> 0.6566799
B53: Balance Sheet
B55: Equity Share Capital | C55: =IFERROR('[2]Data Sheet'!C57,0) -> 289.37 | D55: =IFERROR('[2]Data Sheet'!D57,0) -> 289.37 | E55: =IFERROR('[2]Data Sheet'!E57,0) -> 289.37 | F55: =IFERROR('[2]Data Sheet'!F57,0) -> 289.37 | G55: =IFERROR('[2]Data Sheet'!G57,0) -> 289.37 | H55: =IFERROR('[2]Data Sheet'!H57,0) -> 289.37 | I55: =IFERROR('[2]Data Sheet'!I57,0) -> 282.96 | J55: =IFERROR('[2]Data Sheet'!J57,0) -> 279.18 | K55: =IFERROR('[2]Data Sheet'!K57,0) -> 279.26
A56: # | B56: Reserves | C56: =IFERROR('[2]Data Sheet'!C58,0) -> 17567.2 | D56: =IFERROR('[2]Data Sheet'!D58,0) -> 20135.87 | E56: =IFERROR('[2]Data Sheet'!E58,0) -> 22944.44 | F56: =IFERROR('[2]Data Sheet'!F58,0) -> 21372.71 | G56: =IFERROR('[2]Data Sheet'!G58,0) -> 26984.06 | H56: =IFERROR('[2]Data Sheet'!H58,0) -> 29570.28 | I56: =IFERROR('[2]Data Sheet'!I58,0) -> 29078.58 | J56: =IFERROR('[2]Data Sheet'!J58,0) -> 28683.23 | K56: =IFERROR('[2]Data Sheet'!K58,0) -> 34909.48
B57: Borrowings | C57: =IFERROR('[2]Data Sheet'!C59,0) -> 119.9 | D57: =IFERROR('[2]Data Sheet'!D59,0) -> 120.77 | E57: =IFERROR('[2]Data Sheet'!E59,0) -> 124.52 | F57: =IFERROR('[2]Data Sheet'!F59,0) -> 125.59 | G57: =IFERROR('[2]Data Sheet'!G59,0) -> 121.46 | H57: =IFERROR('[2]Data Sheet'!H59,0) -> 122.77 | I57: =IFERROR('[2]Data Sheet'!I59,0) -> 124.23 | J57: =IFERROR('[2]Data Sheet'!J59,0) -> 1911.74 | K57: =IFERROR('[2]Data Sheet'!K59,0) -> 9364.16
B58: Other Liabilities | C58: =IFERROR('[2]Data Sheet'!C60,0) -> 3661.15 | D58: =IFERROR('[2]Data Sheet'!D60,0) -> 4594.99 | E58: =IFERROR('[2]Data Sheet'!E60,0) -> 5476.08 | F58: =IFERROR('[2]Data Sheet'!F60,0) -> 4722.35 | G58: =IFERROR('[2]Data Sheet'!G60,0) -> 6206.82 | H58: =IFERROR('[2]Data Sheet'!H60,0) -> 5128.79 | I58: =IFERROR('[2]Data Sheet'!I60,0) -> 5650.68 | J58: =IFERROR('[2]Data Sheet'!J60,0) -> 8469.54 | K58: =IFERROR('[2]Data Sheet'!K60,0) -> 9557.02
B59: Total Liabilities | C59: =IFERROR(SUM(C55:C58),0) -> 21637.62 | D59: =IFERROR(SUM(D55:D58),0) -> 25141 | E59: =IFERROR(SUM(E55:E58),0) -> 28834.41 | F59: =IFERROR(SUM(F55:F58),0) -> 26510.02 | G59: =IFERROR(SUM(G55:G58),0) -> 33601.71 | H59: =IFERROR(SUM(H55:H58),0) -> 35111.21 | I59: =IFERROR(SUM(I55:I58),0) -> 35136.45 | J59: =IFERROR(SUM(J55:J58),0) -> 39343.69 | K59: =IFERROR(SUM(K55:K58),0) -> 54109.92
B61: Fixed Assets Net Block | C61: =IFERROR('[2]Data Sheet'!C62,0) -> 2001.79 | D61: =IFERROR('[2]Data Sheet'!D62,0) -> 1878.33 | E61: =IFERROR('[2]Data Sheet'!E62,0) -> 1763.94 | F61: =IFERROR('[2]Data Sheet'!F62,0) -> 1699.02 | G61: =IFERROR('[2]Data Sheet'!G62,0) -> 1667.55 | H61: =IFERROR('[2]Data Sheet'!H62,0) -> 1836.05 | I61: =IFERROR('[2]Data Sheet'!I62,0) -> 2842.24 | J61: =IFERROR('[2]Data Sheet'!J62,0) -> 3217.37 | K61: =IFERROR('[2]Data Sheet'!K62,0) -> 3676.59
...

Sheet Forcasting
B2: Return on Equity(ROE) | C2: Return on Equity(ROE) | D2: Return on Equity(ROE) | E2: Return on Equity(ROE) | F2: Return on Equity(ROE) | G2: Return on Equity(ROE) | H2: Return on Equity(ROE) | I2: Return on Equity(ROE) | J2: Return on Equity(ROE)
B4: ='[2]Data Sheet'!B1 -> BAJAJ AUTO LTD
B5: =CONCATENATE(" ",VLOOKUP(B4,'[2]LIST OF STOCKS'!B5:D5444,3,FALSE)," | ","Bse Code: ",VLOOKUP(B4,'[2]LIST OF STOCKS'!B5:E5444,2,FALSE),) -> BAJAJ-AUTO | Bse Code: 532977
B10: ="Sales Forcasting - "&'[2]Balance Sheet'!A1 -> Sales Forcasting - BAJAJ AUTO LTD
B11: Year Weight | C11: Year | D11: Sales | E11: Sales Growth
B12: 1 | C12: 2017A | D12: {=TRANSPOSE('[2]Data Sheet'!C17:I17)} -> 21754.72
B13: 2 | C13: 2018A | D13: 25209.93 | E13: =D13/D12-1 -> 0.15882576
B14: 3 | C14: 2019A | D14: 30357.63 | E14: =D14/D13-1 -> 0.20419335
B15: 4 | C15: 2020A | D15: 29918.65 | E15: =D15/D14-1 -> -0.014460286
B16: 5 | C16: 2021A | D16: 27741.08 | E16: =D16/D15-1 -> -0.07278303
B17: 6 | C17: 2022A | D17: 33144.71 | E17: =D17/D16-1 -> 0.19478802
B18: 7 | C18: 2023A | D18: 36455.38 | E18: =D18/D17-1 -> 0.099885321
B19: 8 | C19: 2024A | D19: ='[2]Data Sheet'!J17 -> 44870.43 | E19: =D19/D18-1 -> 0.2308315
B20: 9 | C20: 2025A | D20: ='[2]Data Sheet'!K17 -> 50994.55 | E20: =D20/D19-1 -> 0.13648454
B21: 10 | C21: 2026E | D21: =FORECAST(B21,$D$12:$D$20,$B$12:$B$20) -> 49329.874 | E21: =D21/D20-1 -> -0.032644197
B22: 11 | C22: 2027E | D22: =FORECAST(B22,$D$12:$D$20,$B$12:$B$20) -> 52519.247 | E22: =D22/D21-1 -> 0.064653986
B23: 12 | C23: 2028E | D23: =FORECAST(B23,$D$12:$D$20,$B$12:$B$20) -> 55708.62 | E23: =D23/D22-1 -> 0.060727699
B24: 13 | C24: 2029E | D24: =FORECAST(B24,$D$12:$D$20,$B$12:$B$20) -> 58897.993 | E24: =D24/D23-1 -> 0.057250979
B25: 14 | C25: 2030E | D25: =FORECAST(B25,$D$12:$D$20,$B$12:$B$20) -> 62087.366 | E25: =D25/D24-1 -> 0.054150793
B27: Return on Equity(ROE) | C27: Return on Equity(ROE) | D27: Return on Equity(ROE) | E27: Return on Equity(ROE) | F27: Return on Equity(ROE) | G27: Return on Equity(ROE) | H27: Return on Equity(ROE) | I27: Return on Equity(ROE) | J27: Return on Equity(ROE) | K27: Return on Equity(ROE)
H28: ="EBITDA Forcasting - "&'[2]Balance Sheet'!A1 -> EBITDA Forcasting - BAJAJ AUTO LTD
H29: Year Weight | I29: Year | J29: EBITDA | K29: EBITDA Growth
H30: 1 | I30: 2017A | J30: ='Historical FS'!C25 -> 4341.27
H31: 2 | I31: 2018A | J31: ='Historical FS'!D25 -> 4865.16 | K31: =J31/J30-1 -> 0.12067667
H32: 3 | I32: 2019A | J32: ='Historical FS'!E25 -> 5085.08 | K32: =J32/J31-1 -> 0.045203035
H33: 4 | I33: 2020A | J33: ='Historical FS'!F25 -> 4983.32 | K33: =J33/J32-1 -> -0.020011485
H34: 5 | I34: 2021A | J34: ='Historical FS'!G25 -> 4498.82 | K34: =J34/J33-1 -> -0.09722434
H35: 6 | I35: 2022A | J35: ='Historical FS'!H25 -> 5634.72 | K35: =J35/J34-1 -> 0.25248843
H36: 7 | I36: 2023A | J36: ='Historical FS'!I25 -> 6263.98 | K36: =J36/J35-1 -> 0.11167547
H37: 8 | I37: 2024A | J37: ='Historical FS'!J25 -> 8612 | K37: =J37/J36-1 -> 0.37484475
H38: 9 | I38: 2025A | J38: ='Historical FS'!K25 -> 9611.42 | K38: =J38/J37-1 -> 0.1160497
H39: 10 | I39: 2026E | J39: =FORECAST(H39,$J$30:$J$38,$H$30:$H$38) -> 8932.6122 | K39: =J39/J38-1 -> -0.070625129
H40: 11 | I40: 2027E | J40: =FORECAST(H40,$J$30:$J$38,$H$30:$H$38) -> 9521.4509 | K40: =J40/J39-1 -> 0.065920097
H41: 12 | I41: 2028E | J41: =FORECAST(H41,$J$30:$J$38,$H$30:$H$38) -> 10110.29 | K41: =J41/J40-1 -> 0.061843376
H42: 13 | I42: 2029E | J42: =FORECAST(H42,$J$30:$J$38,$H$30:$H$38) -> 10699.128 | K42: =J42/J41-1 -> 0.058241523
H43: 14 | I43: 2030E | J43: =FORECAST(H43,$J$30:$J$38,$H$30:$H$38) -> 11287.967 | K43: =J43/J42-1 -> 0.055036135
B46: ="Net Profit Forcasting - "&'[2]Balance Sheet'!A1 -> Net Profit Forcasting - BAJAJ AUTO LTD
B47: =B11 -> Year Weight | C47: =C11 -> Year | D47: Net Profit | E47: Net profit Growth
B48: 1 | C48: =C12 -> 2017A | D48: ='Historical FS'!C40 -> 2524.5099
B49: 2 | C49: =C13 -> 2018A | D49: ='Historical FS'!D40 -> 2834.5799 | E49: =D49/D48-1 -> 0.12282384
...

Sheet Ratio Analysis
B2: Return on Equity(ROE) | C2: Return on Equity(ROE) | D2: Return on Equity(ROE) | E2: Return on Equity(ROE) | F2: Return on Equity(ROE) | G2: Return on Equity(ROE) | H2: Return on Equity(ROE) | I2: Return on Equity(ROE) | L2: Return on Equity(ROE) | M2: Return on Equity(ROE)
B4: ='[2]Data Sheet'!B1 -> BAJAJ AUTO LTD
B5: =CONCATENATE(" ",VLOOKUP(B4,'[2]LIST OF STOCKS'!B5:D5444,3,FALSE)," | ","Bse Code: ",VLOOKUP(B4,'[2]LIST OF STOCKS'!B5:E5444,2,FALSE),) -> BAJAJ-AUTO | Bse Code: 532977
B8: ="Ratio Analysis - "&'[2]Balance Sheet'!A1 -> Ratio Analysis - BAJAJ AUTO LTD
B9: Years | C9: =IFERROR('[2]Data Sheet'!C16,0) -> 42825 | D9: =IFERROR('[2]Data Sheet'!D16,0) -> 43190 | E9: =IFERROR('[2]Data Sheet'!E16,0) -> 43555 | F9: =IFERROR('[2]Data Sheet'!F16,0) -> 43921 | G9: =IFERROR('[2]Data Sheet'!G16,0) -> 44286 | H9: =IFERROR('[2]Data Sheet'!H16,0) -> 44651 | I9: =IFERROR('[2]Data Sheet'!I16,0) -> 45016 | J9: =IFERROR('[2]Data Sheet'!J16,0) -> 45382 | K9: =IFERROR('[2]Data Sheet'!K16,0) -> 45747 | L9: Mean | M9: Median
B11: Sales Growth | C11: - | D11: =IFERROR('Historical FS'!D14,0) -> 0.15882576 | E11: =IFERROR('Historical FS'!E14,0) -> 0.20419335 | F11: =IFERROR('Historical FS'!F14,0) -> -0.014460286 | G11: =IFERROR('Historical FS'!G14,0) -> -0.07278303 | H11: =IFERROR('Historical FS'!H14,0) -> 0.19478802 | I11: =IFERROR('Historical FS'!I14,0) -> 0.099885321 | J11: =IFERROR('Historical FS'!J14,0) -> 0.2308315 | K11: =IFERROR('Historical FS'!K14,0) -> 0.13648454 | L11: =IFERROR(AVERAGE(D11:I11),0) -> 0.095074856 | M11: =IFERROR(MEDIAN(D11:I11),0) -> 0.12935554
B12: EBIT Growth | D12: =IFERROR('Historical FS'!D34/'Historical FS'!C34-1,0) -> 0.12807434 | E12: =IFERROR('Historical FS'!E34/'Historical FS'!D34-1,0) -> 0.058442951 | F12: =IFERROR('Historical FS'!F34/'Historical FS'!E34-1,0) -> -0.01686012 | G12: =IFERROR('Historical FS'!G34/'Historical FS'!F34-1,0) -> -0.10582356 | H12: =IFERROR('Historical FS'!H34/'Historical FS'!G34-1,0) -> 0.26543014 | I12: =IFERROR('Historical FS'!I34/'Historical FS'!H34-1,0) -> 0.10871669 | J12: =IFERROR('Historical FS'!J34/'Historical FS'!I34-1,0) -> 0.37858124 | K12: =IFERROR('Historical FS'!K34/'Historical FS'!J34-1,0) -> 0.075903712 | L12: =IFERROR(AVERAGE(D12:I12),0) -> 0.072996741 | M12: =IFERROR(MEDIAN(D12:I12),0) -> 0.083579821
B13: Net Profit Growth | D13: =IFERROR('Historical FS'!D40/'Historical FS'!C40-1,0) -> 0.12282384 | E13: =IFERROR('Historical FS'!E40/'Historical FS'!D40-1,0) -> -0.016810285 | F13: =IFERROR('Historical FS'!F40/'Historical FS'!E40-1,0) -> 0.16741722 | G13: =IFERROR('Historical FS'!G40/'Historical FS'!F40-1,0) -> -0.12452095 | H13: =IFERROR('Historical FS'!H40/'Historical FS'!G40-1,0) -> 0.35883908 | I13: =IFERROR('Historical FS'!I40/'Historical FS'!H40-1,0) -> 0.073985257 | J13: =IFERROR('Historical FS'!J40/'Historical FS'!I40-1,0) -> 0.40853535 | K13: =IFERROR('Historical FS'!K40/'Historical FS'!J40-1,0) -> 0.0092934382 | L13: =IFERROR(AVERAGE(D13:I13),0) -> 0.096955695 | M13: =IFERROR(MEDIAN(D13:I13),0) -> 0.09840455
B14: Dividend Growth | D14: =IFERROR('Historical FS'!D48/'Historical FS'!C48-1,0) -> 0.090905664 | E14: =IFERROR('Historical FS'!E48/'Historical FS'!D48-1,0) -> 0 | F14: =IFERROR('Historical FS'!F48/'Historical FS'!E48-1,0) -> 1 | G14: =IFERROR('Historical FS'!G48/'Historical FS'!F48-1,0) -> 0.16666667 | H14: =IFERROR('Historical FS'!H48/'Historical FS'!G48-1,0) -> 0 | I14: =IFERROR('Historical FS'!I48/'Historical FS'!H48-1,0) -> -3.7683912e-05 | J14: =IFERROR('Historical FS'!J48/'Historical FS'!I48-1,0) -> -0.42853159 | K14: =IFERROR('Historical FS'!K48/'Historical FS'!J48-1,0) -> 1.6248121 | L14: =IFERROR(AVERAGE(D14:I14),0) -> 0.20958911 | M14: =IFERROR(MEDIAN(D14:I14),0) -> 0.045452832
B15: EBITDA Growth | D15: =IFERROR('Historical FS'!D25/'Historical FS'!C25-1,0) -> 0.12067667 | E15: =IFERROR('Historical FS'!E25/'Historical FS'!D25-1,0) -> 0.045203035 | F15: =IFERROR('Historical FS'!F25/'Historical FS'!E25-1,0) -> -0.020011485 | G15: =IFERROR('Historical FS'!G25/'Historical FS'!F25-1,0) -> -0.09722434 | H15: =IFERROR('Historical FS'!H25/'Historical FS'!G25-1,0) -> 0.25248843 | I15: =IFERROR('Historical FS'!I25/'Historical FS'!H25-1,0) -> 0.11167547 | J15: =IFERROR('Historical FS'!J25/'Historical FS'!I25-1,0) -> 0.37484475 | K15: =IFERROR('Historical FS'!K25/'Historical FS'!J25-1,0) -> 0.1160497 | L15: =IFERROR(AVERAGE(D15:I15),0) -> 0.068801296 | M15: =IFERROR(MEDIAN(D15:I15),0) -> 0.078439252
B17: Gross Margin | C17: =IFERROR('Historical FS'!C20,0) -> 0.2481935 | D17: =IFERROR('Historical FS'!D20,0) -> 0.24181701 | E17: =IFERROR('Historical FS'!E20,0) -> 0.21206497 | F17: =IFERROR('Historical FS'!F20,0) -> 0.21972749 | G17: =IFERROR('Historical FS'!G20,0) -> 0.20575803 | H17: =IFERROR('Historical FS'!H20,0) -> 0.20759029 | I17: =IFERROR('Historical FS'!I20,0) -> 0.21339018 | J17: =IFERROR('Historical FS'!J20,0) -> 0.229797 | K17: =IFERROR('Historical FS'!K20,0) -> 0.25236716 | L17: =IFERROR(AVERAGE(C17:I17),0) -> 0.22122021 | M17: =IFERROR(MEDIAN(C17:I17),0) -> 0.21339018
B18: EBITDA margin | C18: =IFERROR('Historical FS'!C26,0) -> 0.19955531 | D18: =IFERROR('Historical FS'!D26,0) -> 0.19298586 | E18: =IFERROR('Historical FS'!E26,0) -> 0.16750583 | F18: =IFERROR('Historical FS'!F26,0) -> 0.16656233 | G18: =IFERROR('Historical FS'!G26,0) -> 0.16217177 | H18: =IFERROR('Historical FS'!H26,0) -> 0.1700036 | I18: =IFERROR('Historical FS'!I26,0) -> 0.17182594 | J18: =IFERROR('Historical FS'!J26,0) -> 0.19193041 | K18: =IFERROR('Historical FS'!K26,0) -> 0.18847936 | L18: =IFERROR(AVERAGE(C18:I18),0) -> 0.17580152 | M18: =IFERROR(MEDIAN(C18:I18),0) -> 0.1700036
B19: EBIT margin | C19: =IFERROR(('Historical FS'!C25-'Historical FS'!C31)/'Historical FS'!C13,0) -> 0.1854301 | D19: =IFERROR(('Historical FS'!D25-'Historical FS'!D31)/'Historical FS'!D13,0) -> 0.18049872 | E19: =IFERROR(('Historical FS'!E25-'Historical FS'!E31)/'Historical FS'!E13,0) -> 0.15875383 | F19: =IFERROR(('Historical FS'!F25-'Historical FS'!F31)/'Historical FS'!F13,0) -> 0.15832566 | G19: =IFERROR(('Historical FS'!G25-'Historical FS'!G31)/'Historical FS'!G13,0) -> 0.1528221 | H19: =IFERROR(('Historical FS'!H25-'Historical FS'!H31)/'Historical FS'!H13,0) -> 0.16186474 | I19: =IFERROR(('Historical FS'!I25-'Historical FS'!I31)/'Historical FS'!I13,0) -> 0.16398485 | J19: =IFERROR(('Historical FS'!J25-'Historical FS'!J31)/'Historical FS'!J13,0) -> 0.183801 | K19: =IFERROR(('Historical FS'!K25-'Historical FS'!K31)/'Historical FS'!K13,0) -> 0.18035633 | L19: =IFERROR(AVERAGE(C19:I19),0) -> 0.16595429 | M19: =IFERROR(MEDIAN(C19:I19),0) -> 0.16186474
B20: EBT Margin | C20: =IFERROR('Historical FS'!C23,0) -> 0.048638181 | D20: =IFERROR('Historical FS'!D23,0) -> 0.048831155 | E20: =IFERROR('Historical FS'!E23,0) -> 0.044559144 | F20: =IFERROR('Historical FS'!F23,0) -> 0.053165166 | G20: =IFERROR('Historical FS'!G23,0) -> 0.043586263 | H20: =IFERROR('Historical FS'!H23,0) -> 0.037586692 | I20: =IFERROR('Historical FS'!I23,0) -> 0.041564236 | J20: =IFERROR('Historical FS'!J23,0) -> 0.037866586 | K20: =IFERROR('Historical FS'!K23,0) -> 0.063887808 | L20: =IFERROR(AVERAGE(C20:I20),0) -> 0.045418691 | M20: =IFERROR(MEDIAN(C20:I20),0) -> 0.044559144
B21: Net profit Margin | C21: =IFERROR('Historical FS'!C41,0) -> 0.11604424 | D21: =IFERROR('Historical FS'!D41,0) -> 0.11243902 | E21: =IFERROR('Historical FS'!E41,0) -> 0.091803275 | F21: =IFERROR('Historical FS'!F41,0) -> 0.10874521 | G21: =IFERROR('Historical FS'!G41,0) -> 0.10267732 | H21: =IFERROR('Historical FS'!H41,0) -> 0.11677549 | I21: =IFERROR('Historical FS'!I41,0) -> 0.11402566 | J21: =IFERROR('Historical FS'!J41,0) -> 0.13048836 | K21: =IFERROR('Historical FS'!K41,0) -> 0.11588459 | L21: =IFERROR(AVERAGE(C21:I21),0) -> 0.10893003 | M21: =IFERROR(MEDIAN(C21:I21),0) -> 0.11243902
B23: Sales expenses % sales | C23: =IFERROR('Historical FS'!C23,0) -> 0.048638181 | D23: =IFERROR('Historical FS'!D23,0) -> 0.048831155 | E23: =IFERROR('Historical FS'!E23,0) -> 0.044559144 | F23: =IFERROR('Historical FS'!F23,0) -> 0.053165166 | G23: =IFERROR('Historical FS'!G23,0) -> 0.043586263 | H23: =IFERROR('Historical FS'!H23,0) -> 0.037586692 | I23: =IFERROR('Historical FS'!I23,0) -> 0.041564236 | J23: =IFERROR('Historical FS'!J23,0) -> 0.037866586 | K23: =IFERROR('Historical FS'!K23,0) -> 0.063887808 | L23: =IFERROR(AVERAGE(C23:I23),0) -> 0.045418691 | M23: =IFERROR(MEDIAN(C23:I23),0) -> 0.044559144
B24: Depreciation % sales | C24: =IFERROR('Historical FS'!C32,0) -> 0.014125211 | D24: =IFERROR('Historical FS'!D32,0) -> 0.012487143 | E24: =IFERROR('Historical FS'!E32,0) -> 0.0087520007 | F24: =IFERROR('Historical FS'!F32,0) -> 0.0082366684 | G24: =IFERROR('Historical FS'!G32,0) -> 0.009349672 | H24: =IFERROR('Historical FS'!H32,0) -> 0.0081388553 | I24: =IFERROR('Historical FS'!I32,0) -> 0.0078410923 | J24: =IFERROR('Historical FS'!J32,0) -> 0.0081294073 | K24: =IFERROR('Historical FS'!K32,0) -> 0.0081230249 | L24: =IFERROR(AVERAGE(C24:I24),0) -> 0.0098472346 | M24: =IFERROR(MEDIAN(C24:I24),0) -> 0.0087520007
B25: Operating Income % Sales | C25: =C19 -> 0.1854301 | D25: =D19 -> 0.18049872 | E25: =E19 -> 0.15875383 | F25: =F19 -> 0.15832566 | G25: =G19 -> 0.1528221 | H25: =H19 -> 0.16186474 | I25: =I19 -> 0.16398485 | J25: =J19 -> 0.183801 | K25: =K19 -> 0.18035633 | L25: =IFERROR(AVERAGE(C25:I25),0) -> 0.16595429 | M25: =IFERROR(MEDIAN(C25:I25),0) -> 0.16186474
B27: Return on Capital Employed | C27: =IFERROR(('Historical FS'!C25-'Historical FS'!C31)/(SUM('Historical FS'!C55:C57)),0) -> 0.22440335 | D27: =IFERROR(('Historical FS'!D25-'Historical FS'!D31)/(SUM('Historical FS'!D55:D57)),0) -> 0.22147171 | E27: =IFERROR(('Historical FS'!E25-'Historical FS'!E31)/(SUM('Historical FS'!E55:E57)),0) -> 0.20632425 | F27: =IFERROR(('Historical FS'!F25-'Historical FS'!F31)/(SUM('Historical FS'!F55:F57)),0) -> 0.2174115 | G27: =IFERROR(('Historical FS'!G25-'Historical FS'!G31)/(SUM('Historical FS'!G55:G57)),0) -> 0.15475331 | H27: =IFERROR(('Historical FS'!H25-'Historical FS'!H31)/(SUM('Historical FS'!H55:H57)),0) -> 0.17893686 | I27: =IFERROR(('Historical FS'!I25-'Historical FS'!I31)/(SUM('Historical FS'!I55:I57)),0) -> 0.20274627 | J27: =IFERROR(('Historical FS'!J25-'Historical FS'!J31)/(SUM('Historical FS'!J55:J57)),0) -> 0.26712412 | K27: =IFERROR(('Historical FS'!K25-'Historical FS'!K31)/(SUM('Historical FS'!K55:K57)),0) -> 0.20643303 | L27: =IFERROR(AVERAGE(C27:I27),0) -> 0.20086389 | M27: =IFERROR(MEDIAN(C27:I27),0) -> 0.20632425
B28: Retained Earnings% | C28: =IFERROR('Historical FS'!C51,0) -> 0.36956477 | D28: =IFERROR('Historical FS'!D51,0) -> 0.38748597 | E28: =IFERROR('Historical FS'!E51,0) -> 0.37701338 | F28: =IFERROR('Historical FS'!F51,0) -> -0.067290438 | G28: =IFERROR('Historical FS'!G51,0) -> -0.42227524 | H28: =IFERROR('Historical FS'!H51,0) -> -0.046684082 | I28: =IFERROR('Historical FS'!I51,0) -> 0.047008905 | J28: =IFERROR('Historical FS'!J51,0) -> 0.61854589 | K28: =IFERROR('Historical FS'!K51,0) -> 0.0076186662 | L28: =IFERROR(AVERAGE(C28:I28),0) -> 0.09211761 | M28: =IFERROR(MEDIAN(C28:I28),0) -> 0.047008905
B29: Return of Equity% | C29: =IFERROR('Historical FS'!C40/SUM('Historical FS'!C55:C56),0) -> 0.14137709 | D29: =IFERROR('Historical FS'!D40/SUM('Historical FS'!D55:D56),0) -> 0.13877829 | E29: =IFERROR('Historical FS'!E40/SUM('Historical FS'!E55:E56),0) -> 0.11995148 | F29: =IFERROR('Historical FS'!F40/SUM('Historical FS'!F55:F56),0) -> 0.15019379 | G29: =IFERROR('Historical FS'!G40/SUM('Historical FS'!G55:G56),0) -> 0.1044379 | H29: =IFERROR('Historical FS'!H40/SUM('Historical FS'!H55:H56),0) -> 0.12962274 | I29: =IFERROR('Historical FS'!I40/SUM('Historical FS'!I55:I56),0) -> 0.14157462 | J29: =IFERROR('Historical FS'!J40/SUM('Historical FS'!J55:J56),0) -> 0.20216096 | K29: =IFERROR('Historical FS'!K40/SUM('Historical FS'!K55:K56),0) -> 0.16793674 | L29: =IFERROR(AVERAGE(C29:I29),0) -> 0.13227656 | M29: =IFERROR(MEDIAN(C29:I29),0) -> 0.13877829
B30: Self Sustained Growth Rate | C30: =IFERROR(C28*C29,0) -> 0.052247993 | D30: =IFERROR(D28*D29,0) -> 0.053774641 | E30: =IFERROR(E28*E29,0) -> 0.045223313 | F30: =IFERROR(F28*F29,0) -> -0.010106606 | G30: =IFERROR(G28*G29,0) -> -0.044101539 | H30: =IFERROR(H28*H29,0) -> -0.0060513188 | I30: =IFERROR(I28*I29,0) -> 0.006655268 | J30: =IFERROR(J28*J29,0) -> 0.12504583 | K30: =IFERROR(K28*K29,0) -> 0.001279454 | L30: =IFERROR(AVERAGE(C30:I30),0) -> 0.013948821 | M30: =IFERROR(MEDIAN(C30:I30),0) -> 0.006655268
B31: Interest Coverage Ratio | C31: =('Historical FS'!C25-'Historical FS'!C31)/'Historical FS'!C28 -> 2881.4143 | D31: =('Historical FS'!D25-'Historical FS'!D31)/'Historical FS'!D28 -> 3473.5573 | E31: =('Historical FS'!E25-'Historical FS'!E31)/'Historical FS'!E28 -> 1075.7567 | F31: =('Historical FS'!F25-'Historical FS'!F31)/'Historical FS'!F28 -> 1499.0158 | G31: =('Historical FS'!G25-'Historical FS'!G31)/'Historical FS'!G28 -> 636.55405 | H31: =('Historical FS'!H25-'Historical FS'!H31)/'Historical FS'!H28 -> 619.51039 | I31: =('Historical FS'!I25-'Historical FS'!I31)/'Historical FS'!I28 -> 151.30676 | J31: =('Historical FS'!J25-'Historical FS'!J31)/'Historical FS'!J28 -> 136.63403 | K31: =('Historical FS'!K25-'Historical FS'!K31)/'Historical FS'!K28 -> 23.649241 | L31: =IFERROR(AVERAGE(C31:I31),0) -> 1476.7308 | M31: =IFERROR(MEDIAN(C31:I31),0) -> 1075.7567
B33: Debtor Turnover Ratio | C33: =IFERROR('Historical FS'!C13/'Historical FS'!C67,0) -> 22.820674 | D33: =IFERROR('Historical FS'!D13/'Historical FS'!D67,0) -> 16.898208 | E33: =IFERROR('Historical FS'!E13/'Historical FS'!E67,0) -> 11.859885 | F33: =IFERROR('Historical FS'!F13/'Historical FS'!F67,0) -> 17.34314 | G33: =IFERROR('Historical FS'!G13/'Historical FS'!G67,0) -> 10.210751 | H33: =IFERROR('Historical FS'!H13/'Historical FS'!H67,0) -> 21.857786 | I33: =IFERROR('Historical FS'!I13/'Historical FS'!I67,0) -> 20.80276 | J33: =IFERROR('Historical FS'!J13/'Historical FS'!J67,0) -> 21.618782 | K33: =IFERROR('Historical FS'!K13/'Historical FS'!K67,0) -> 23.994951 | L33: =IFERROR(AVERAGE(C33:I33),0) -> 17.399029 | M33: =IFERROR(MEDIAN(C33:I33),0) -> 17.34314
B34: Creditor Turnover Ratio | C34: =IFERROR('Historical FS'!C13/'Historical FS'!C58,0) -> 5.9420455 | D34: =IFERROR('Historical FS'!D13/'Historical FS'!D58,0) -> 5.486395 | E34: =IFERROR('Historical FS'!E13/'Historical FS'!E58,0) -> 5.5436791 | F34: =IFERROR('Historical FS'!F13/'Historical FS'!F58,0) -> 6.3355427 | G34: =IFERROR('Historical FS'!G13/'Historical FS'!G58,0) -> 4.4694513 | H34: =IFERROR('Historical FS'!H13/'Historical FS'!H58,0) -> 6.4624814 | I34: =IFERROR('Historical FS'!I13/'Historical FS'!I58,0) -> 6.4515032 | J34: =IFERROR('Historical FS'!J13/'Historical FS'!J58,0) -> 5.2978592 | K34: =IFERROR('Historical FS'!K13/'Historical FS'!K58,0) -> 5.3358212 | L34: =IFERROR(AVERAGE(C34:I34),0) -> 5.813014 | M34: =IFERROR(MEDIAN(C34:I34),0) -> 5.9420455
B35: Inventory Turnover Ratio | C35: =IFERROR('Historical FS'!C13/'Historical FS'!C68,0) -> 29.867267 | D35: =IFERROR('Historical FS'!D13/'Historical FS'!D68,0) -> 33.94911 | E35: =IFERROR('Historical FS'!E13/'Historical FS'!E68,0) -> 31.57287 | F35: =IFERROR('Historical FS'!F13/'Historical FS'!F68,0) -> 28.132252 | G35: =IFERROR('Historical FS'!G13/'Historical FS'!G68,0) -> 18.569694 | H35: =IFERROR('Historical FS'!H13/'Historical FS'!H68,0) -> 26.93575 | I35: =IFERROR('Historical FS'!I13/'Historical FS'!I68,0) -> 23.315775 | J35: =IFERROR('Historical FS'!J13/'Historical FS'!J68,0) -> 26.570203 | K35: =IFERROR('Historical FS'!K13/'Historical FS'!K68,0) -> 24.547767 | L35: =IFERROR(AVERAGE(C35:I35),0) -> 27.477531 | M35: =IFERROR(MEDIAN(C35:I35),0) -> 28.132252
B36: Fixed Asset Turnover Ratio | C36: =IFERROR('Historical FS'!C13/'Historical FS'!C61,0) -> 10.867633 | D36: =IFERROR('Historical FS'!D13/'Historical FS'!D61,0) -> 13.421459 | E36: =IFERROR('Historical FS'!E13/'Historical FS'!E61,0) -> 17.210126 | F36: =IFERROR('Historical FS'!F13/'Historical FS'!F61,0) -> 17.609357 | G36: =IFERROR('Historical FS'!G13/'Historical FS'!G61,0) -> 16.635831 | H36: =IFERROR('Historical FS'!H13/'Historical FS'!H61,0) -> 18.052183 | I36: =IFERROR('Historical FS'!I13/'Historical FS'!I61,0) -> 12.826285 | J36: =IFERROR('Historical FS'!J13/'Historical FS'!J61,0) -> 13.946307 | K36: =IFERROR('Historical FS'!K13/'Historical FS'!K61,0) -> 13.870067 | L36: =IFERROR(AVERAGE(C36:I36),0) -> 15.231839 | M36: =IFERROR(MEDIAN(C36:I36),0) -> 16.635831
B37: Capital Turnover Ratio | C37: =IFERROR('Historical FS'!C13/SUM('Historical FS'!C55:C56),0) -> 1.2183034 | D37: =IFERROR('Historical FS'!D13/SUM('Historical FS'!D55:D56),0) -> 1.2342538 | E37: =IFERROR('Historical FS'!E13/SUM('Historical FS'!E55:E56),0) -> 1.3066144 | F37: =IFERROR('Historical FS'!F13/SUM('Historical FS'!F55:F56),0) -> 1.3811531 | G37: =IFERROR('Historical FS'!G13/SUM('Historical FS'!G55:G56),0) -> 1.0171467 | H37: =IFERROR('Historical FS'!H13/SUM('Historical FS'!H55:H56),0) -> 1.1100167 | I37: =IFERROR('Historical FS'!I13/SUM('Historical FS'!I55:I56),0) -> 1.2416031 | J37: =IFERROR('Historical FS'!J13/SUM('Historical FS'!J55:J56),0) -> 1.5492644 | K37: =IFERROR('Historical FS'!K13/SUM('Historical FS'!K55:K56),0) -> 1.4491724 | L37: =IFERROR(AVERAGE(C37:I37),0) -> 1.2155845 | M37: =IFERROR(MEDIAN(C37:I37),0) -> 1.2342538
B39: Debtor Days | C39: =IFERROR(365/C33,0) -> 15.994269 | D39: =IFERROR(365/D33,0) -> 21.599923 | E39: =IFERROR(365/E33,0) -> 30.776014 | F39: =IFERROR(365/F33,0) -> 21.045786 | G39: =IFERROR(365/G33,0) -> 35.746635 | H39: =IFERROR(365/H33,0) -> 16.698855 | I39: =IFERROR(365/I33,0) -> 17.545749 | J39: =IFERROR(365/J33,0) -> 16.883468 | K39: =IFERROR(365/K33,0) -> 15.211533 | L39: =IFERROR(AVERAGE(C39:I39),0) -> 22.772462 | M39: =IFERROR(MEDIAN(C39:I39),0) -> 21.045786
B40: Payble Days | C40: =IFERROR(365/C34,0) -> 61.426658 | D40: =IFERROR(365/D34,0) -> 66.528203 | E40: =IFERROR(365/E34,0) -> 65.840752 | F40: =IFERROR(365/F34,0) -> 57.611481 | G40: =IFERROR(365/G34,0) -> 81.665505 | H40: =IFERROR(365/H34,0) -> 56.479853 | I40: =IFERROR(365/I34,0) -> 56.575962 | J40: =IFERROR(365/J34,0) -> 68.895754 | K40: =IFERROR(365/K34,0) -> 68.40559 | L40: =IFERROR(AVERAGE(C40:I40),0) -> 63.732631 | M40: =IFERROR(MEDIAN(C40:I40),0) -> 61.426658
B41: Inventory Trunover | C41: =IFERROR(365/C35,0) -> 12.220736 | D41: =IFERROR(365/D35,0) -> 10.751386 | E41: =IFERROR(365/E35,0) -> 11.560558 | F41: =IFERROR(365/F35,0) -> 12.974432 | G41: =IFERROR(365/G35,0) -> 19.655682 | H41: =IFERROR(365/H35,0) -> 13.550764 | I41: =IFERROR(365/I35,0) -> 15.654637 | J41: =IFERROR(365/J35,0) -> 13.737193 | K41: =IFERROR(365/K35,0) -> 14.868969 | L41: =IFERROR(AVERAGE(C41:I41),0) -> 13.766885 | M41: =IFERROR(MEDIAN(C41:I41),0) -> 12.974432
B42: Cash Conversion Cycle | C42: =IFERROR(SUM(C39,C41)-C40,0) -> -33.211652 | D42: =IFERROR(SUM(D39,D41)-D40,0) -> -34.176894 | E42: =IFERROR(SUM(E39,E41)-E40,0) -> -23.50418 | F42: =IFERROR(SUM(F39,F41)-F40,0) -> -23.591263 | G42: =IFERROR(SUM(G39,G41)-G40,0) -> -26.263188 | H42: =IFERROR(SUM(H39,H41)-H40,0) -> -26.230234 | I42: =IFERROR(SUM(I39,I41)-I40,0) -> -23.375576 | J42: =IFERROR(SUM(J39,J41)-J40,0) -> -38.275093 | K42: =IFERROR(SUM(K39,K41)-K40,0) -> -38.325088 | L42: =IFERROR(AVERAGE(C42:I42),0) -> -27.193284 | M42: =IFERROR(MEDIAN(C42:I42),0) -> -26.230234
B44: CFO/Sales | C44: =IFERROR('Historical FS'!C86/'Historical FS'!C13,0) -> 0.15739113 | D44: =IFERROR('Historical FS'!#REF!/'Historical FS'!D13,0) -> 0 | E44: =IFERROR('Historical FS'!D86/'Historical FS'!E13,0) -> 0.17850537 | F44: =IFERROR('Historical FS'!E86/'Historical FS'!F13,0) -> 0.056453082 | G44: =IFERROR('Historical FS'!F86/'Historical FS'!G13,0) -> 0.15201283 | H44: =IFERROR('Historical FS'!G86/'Historical FS'!H13,0) -> 0.079017134 | I44: =IFERROR('Historical FS'!H86/'Historical FS'!I13,0) -> 0.13155809 | J44: =IFERROR('Historical FS'!I86/'Historical FS'!J13,0) -> 0.13070969 | K44: =IFERROR('Historical FS'!J86/'Historical FS'!K13,0) -> 0.13175918 | L44: =IFERROR(AVERAGE(C44:I44),0) -> 0.10784823 | M44: =IFERROR(MEDIAN(C44:I44),0) -> 0.13155809
B45: CFO/Total Asests | C45: =IFERROR('Historical FS'!C86/'Historical FS'!C72,0) -> 0.15824291 | D45: =IFERROR('Historical FS'!#REF!/'Historical FS'!D72,0) -> 0 | E45: =IFERROR('Historical FS'!D86/'Historical FS'!E72,0) -> 0.18793518 | F45: =IFERROR('Historical FS'!E86/'Historical FS'!F72,0) -> 0.063711759 | G45: =IFERROR('Historical FS'!F86/'Historical FS'!G72,0) -> 0.12549957 | H45: =IFERROR('Historical FS'!G86/'Historical FS'!H72,0) -> 0.074591562 | I45: =IFERROR('Historical FS'!H86/'Historical FS'!I72,0) -> 0.13649643 | J45: =IFERROR('Historical FS'!I86/'Historical FS'!J72,0) -> 0.14907092 | K45: =IFERROR('Historical FS'!J86/'Historical FS'!K72,0) -> 0.12417316 | L45: =IFERROR(AVERAGE(C45:I45),0) -> 0.10663963 | M45: =IFERROR(MEDIAN(C45:I45),0) -> 0.12549957
B46: CFO/Total Debt | C46: =IFERROR('Historical FS'!C86/'Historical FS'!C57,0) -> 28.557131 | D46: =IFERROR('Historical FS'!#REF!/'Historical FS'!D57,0) -> 0 | E46: =IFERROR('Historical FS'!D86/'Historical FS'!E57,0) -> 43.519113 | F46: =IFERROR('Historical FS'!E86/'Historical FS'!F57,0) -> 13.448523 | G46: =IFERROR('Historical FS'!F86/'Historical FS'!G57,0) -> 34.719249 | H46: =IFERROR('Historical FS'!G86/'Historical FS'!H57,0) -> 21.332573 | I46: =IFERROR('Historical FS'!H86/'Historical FS'!I57,0) -> 38.605812 | J46: =IFERROR('Historical FS'!I86/'Historical FS'!J57,0) -> 3.0678858 | K46: =IFERROR('Historical FS'!J86/'Historical FS'!K57,0) -> 0.71752298 | L46: =IFERROR(AVERAGE(C46:I46),0) -> 25.740343 | M46: =IFERROR(MEDIAN(C46:I46),0) -> 28.557131
B48: Return on Equity(ROE) | C48: Return on Equity(ROE) | D48: Return on Equity(ROE) | E48: Return on Equity(ROE) | F48: Return on Equity(ROE) | G48: Return on Equity(ROE) | H48: Return on Equity(ROE) | I48: Return on Equity(ROE) | L48: Return on Equity(ROE) | M48: Return on Equity(ROE)

Sheet Common Size Statement
B2: Return on Equity(ROE) | C2: Return on Equity(ROE) | D2: Return on Equity(ROE) | E2: Return on Equity(ROE) | F2: Return on Equity(ROE) | G2: Return on Equity(ROE) | H2: Return on Equity(ROE) | I2: Return on Equity(ROE) | J2: Return on Equity(ROE) | K2: Return on Equity(ROE)
B4: ='[2]Data Sheet'!B1 -> BAJAJ AUTO LTD
B5: =CONCATENATE(" ",VLOOKUP(B4,'[2]LIST OF STOCKS'!B5:D5444,3,FALSE)," | ","Bse Code: ",VLOOKUP(B4,'[2]LIST OF STOCKS'!B5:E5444,2,FALSE),) -> BAJAJ-AUTO | Bse Code: 532977
B8: ="Common Size Income Statement"&" "&" - "&'[2]Data Sheet'!$B$1 -> Common Size Income Statement - BAJAJ AUTO LTD | J8: Return on Equity(ROE) | K8: Return on Equity(ROE)
B11: Particulars | C11: ='[2]Data Sheet'!C16 -> 42825 | D11: ='[2]Data Sheet'!D16 -> 43190 | E11: ='[2]Data Sheet'!E16 -> 43555 | F11: ='[2]Data Sheet'!F16 -> 43921 | G11: ='[2]Data Sheet'!G16 -> 44286 | H11: ='[2]Data Sheet'!H16 -> 44651 | I11: ='[2]Data Sheet'!I16 -> 45016 | J11: ='[2]Data Sheet'!J16 -> 45382 | K11: ='[2]Data Sheet'!K16 -> 45747
B13: ='[2]Data Sheet'!A17 -> Sales | C13: ='[2]Data Sheet'!C17/'[2]Data Sheet'!C$17 -> 1 | D13: ='[2]Data Sheet'!D17/'[2]Data Sheet'!D$17 -> 1 | E13: ='[2]Data Sheet'!E17/'[2]Data Sheet'!E$17 -> 1 | F13: ='[2]Data Sheet'!F17/'[2]Data Sheet'!F$17 -> 1 | G13: ='[2]Data Sheet'!G17/'[2]Data Sheet'!G$17 -> 1 | H13: ='[2]Data Sheet'!H17/'[2]Data Sheet'!H$17 -> 1 | I13: ='[2]Data Sheet'!I17/'[2]Data Sheet'!I$17 -> 1 | J13: ='[2]Data Sheet'!J17/'[2]Data Sheet'!J$17 -> 1 | K13: ='[2]Data Sheet'!K17/'[2]Data Sheet'!K$17 -> 1
B14: ='[2]Data Sheet'!A18 -> Raw Material Cost | C14: ='[2]Data Sheet'!C18/'[2]Data Sheet'!C$17 -> 0.67423667 | D14: ='[2]Data Sheet'!D18/'[2]Data Sheet'!D$17 -> 0.69022048 | E14: ='[2]Data Sheet'!E18/'[2]Data Sheet'!E$17 -> 0.71988821 | F14: ='[2]Data Sheet'!F18/'[2]Data Sheet'!F$17 -> 0.70428612 | G14: ='[2]Data Sheet'!G18/'[2]Data Sheet'!G$17 -> 0.71479301 | H14: ='[2]Data Sheet'!H18/'[2]Data Sheet'!H$17 -> 0.72837747 | I14: ='[2]Data Sheet'!I18/'[2]Data Sheet'!I$17 -> 0.71927875 | J14: ='[2]Data Sheet'!J18/'[2]Data Sheet'!J$17 -> 0.71248637 | K14: ='[2]Data Sheet'!K18/'[2]Data Sheet'!K$17 -> 0.69087344
B15: ='[2]Data Sheet'!A19 -> Change in Inventory | C15: ='[2]Data Sheet'!C19/'[2]Data Sheet'!C$17 -> 0.0020078401 | D15: ='[2]Data Sheet'!D19/'[2]Data Sheet'!D$17 -> -0.00038397568 | E15: ='[2]Data Sheet'!E19/'[2]Data Sheet'!E$17 -> 0.0018585114 | F15: ='[2]Data Sheet'!F19/'[2]Data Sheet'!F$17 -> 0.0021060442 | G15: ='[2]Data Sheet'!G19/'[2]Data Sheet'!G$17 -> 0.0079117323 | H15: ='[2]Data Sheet'!H19/'[2]Data Sheet'!H$17 -> -0.0056708899 | I15: ='[2]Data Sheet'!I19/'[2]Data Sheet'!I$17 -> 0.0027521315 | J15: ='[2]Data Sheet'!J19/'[2]Data Sheet'!J$17 -> 0.0017013432 | K15: ='[2]Data Sheet'!K19/'[2]Data Sheet'!K$17 -> -0.00055711836
B16: ='[2]Data Sheet'!A20 -> Power and Fuel | C16: ='[2]Data Sheet'!C20/'[2]Data Sheet'!C$17 -> 0.0044339803 | D16: ='[2]Data Sheet'!D20/'[2]Data Sheet'!D$17 -> 0.0039770043 | E16: ='[2]Data Sheet'!E20/'[2]Data Sheet'!E$17 -> 0.0037885039 | F16: ='[2]Data Sheet'!F20/'[2]Data Sheet'!F$17 -> 0.0038962319 | G16: ='[2]Data Sheet'!G20/'[2]Data Sheet'!G$17 -> 0.0032925899 | H16: ='[2]Data Sheet'!H20/'[2]Data Sheet'!H$17 -> 0.0032587402 | I16: ='[2]Data Sheet'!I20/'[2]Data Sheet'!I$17 -> 0.0033630153 | J16: ='[2]Data Sheet'!J20/'[2]Data Sheet'!J$17 -> 0.0032970489 | K16: ='[2]Data Sheet'!K20/'[2]Data Sheet'!K$17 -> 0.0034697826
B17: ='[2]Data Sheet'!A21 -> Other Mfr. Exp | C17: ='[2]Data Sheet'!C21/'[2]Data Sheet'!C$17 -> 0.025168791 | D17: ='[2]Data Sheet'!D21/'[2]Data Sheet'!D$17 -> 0.021823147 | E17: ='[2]Data Sheet'!E21/'[2]Data Sheet'!E$17 -> 0.020884041 | F17: ='[2]Data Sheet'!F21/'[2]Data Sheet'!F$17 -> 0.023357672 | G17: ='[2]Data Sheet'!G21/'[2]Data Sheet'!G$17 -> 0.021524396 | H17: ='[2]Data Sheet'!H21/'[2]Data Sheet'!H$17 -> 0.025231176 | I17: ='[2]Data Sheet'!I21/'[2]Data Sheet'!I$17 -> 0.020396166 | J17: ='[2]Data Sheet'!J21/'[2]Data Sheet'!J$17 -> 0.016367795 | K17: ='[2]Data Sheet'!K21/'[2]Data Sheet'!K$17 -> 0.015992101
B18: ='[2]Data Sheet'!A22 -> Employee Cost | C18: ='[2]Data Sheet'!C22/'[2]Data Sheet'!C$17 -> 0.045959222 | D18: ='[2]Data Sheet'!D22/'[2]Data Sheet'!D$17 -> 0.04254633 | E18: ='[2]Data Sheet'!E22/'[2]Data Sheet'!E$17 -> 0.041515757 | F18: ='[2]Data Sheet'!F22/'[2]Data Sheet'!F$17 -> 0.046626435 | G18: ='[2]Data Sheet'!G22/'[2]Data Sheet'!G$17 -> 0.046720243 | H18: ='[2]Data Sheet'!H22/'[2]Data Sheet'!H$17 -> 0.041213213 | I18: ='[2]Data Sheet'!I22/'[2]Data Sheet'!I$17 -> 0.040819764 | J18: ='[2]Data Sheet'!J22/'[2]Data Sheet'!J$17 -> 0.036350443 | K18: ='[2]Data Sheet'!K22/'[2]Data Sheet'!K$17 -> 0.037854633
B19: ='[2]Data Sheet'!A23 -> Selling and admin | C19: ='[2]Data Sheet'!C23/'[2]Data Sheet'!C$17 -> 0.032164514 | D19: ='[2]Data Sheet'!D23/'[2]Data Sheet'!D$17 -> 0.033828733 | E19: ='[2]Data Sheet'!E23/'[2]Data Sheet'!E$17 -> 0.030994514 | F19: ='[2]Data Sheet'!F23/'[2]Data Sheet'!F$17 -> 0.034125203 | G19: ='[2]Data Sheet'!G23/'[2]Data Sheet'!G$17 -> 0.023606147 | H19: ='[2]Data Sheet'!H23/'[2]Data Sheet'!H$17 -> 0.019457102 | I19: ='[2]Data Sheet'!I23/'[2]Data Sheet'!I$17 -> 0.023387769 | J19: ='[2]Data Sheet'!J23/'[2]Data Sheet'!J$17 -> 0.022272352 | K19: ='[2]Data Sheet'!K23/'[2]Data Sheet'!K$17 -> 0.024304166
B20: ='[2]Data Sheet'!A24 -> Other Expenses | C20: ='[2]Data Sheet'!C24/'[2]Data Sheet'!C$17 -> 0.016473666 | D20: ='[2]Data Sheet'!D24/'[2]Data Sheet'!D$17 -> 0.015002422 | E20: ='[2]Data Sheet'!E24/'[2]Data Sheet'!E$17 -> 0.013564629 | F20: ='[2]Data Sheet'!F24/'[2]Data Sheet'!F$17 -> 0.019039963 | G20: ='[2]Data Sheet'!G24/'[2]Data Sheet'!G$17 -> 0.019980116 | H20: ='[2]Data Sheet'!H24/'[2]Data Sheet'!H$17 -> 0.01812959 | I20: ='[2]Data Sheet'!I24/'[2]Data Sheet'!I$17 -> 0.018176467 | J20: ='[2]Data Sheet'!J24/'[2]Data Sheet'!J$17 -> 0.015594234 | K20: ='[2]Data Sheet'!K24/'[2]Data Sheet'!K$17 -> 0.039583642
B21: ='[2]Data Sheet'!A25 -> Other Income | C21: ='[2]Data Sheet'!C25/'[2]Data Sheet'!C$17 -> 0.067461682 | D21: ='[2]Data Sheet'!D25/'[2]Data Sheet'!D$17 -> 0.055681234 | E21: ='[2]Data Sheet'!E25/'[2]Data Sheet'!E$17 -> 0.066798034 | F21: ='[2]Data Sheet'!F25/'[2]Data Sheet'!F$17 -> 0.06124541 | G21: ='[2]Data Sheet'!G25/'[2]Data Sheet'!G$17 -> 0.056583233 | H21: ='[2]Data Sheet'!H25/'[2]Data Sheet'!H$17 -> 0.080595063 | I21: ='[2]Data Sheet'!I25/'[2]Data Sheet'!I$17 -> 0.046706412 | J21: ='[2]Data Sheet'!J25/'[2]Data Sheet'!J$17 -> 0.037897787 | K21: ='[2]Data Sheet'!K25/'[2]Data Sheet'!K$17 -> 0.028867006
